Watching for file changes with StatReloader
Watching for file changes with StatReloader
"GET / HTTP/1.1" 200 3766
"GET /favicon.ico HTTP/1.1" 500 59
"POST /api/chatterbot/ HTTP/1.1" 500 59
Watching for file changes with StatReloader
"GET / HTTP/1.1" 200 3766
Not Found: /favicon.ico
"GET /favicon.ico HTTP/1.1" 404 2228
Internal Server Error: /api/chatterbot/
Traceback (most recent call last):
  File "C:\Users\HONG0\.conda\envs\py36\lib\site-packages\django\core\handlers\exception.py", line 47, in inner
    response = get_response(request)
  File "C:\Users\HONG0\.conda\envs\py36\lib\site-packages\django\core\handlers\base.py", line 181, in _get_response
    response = wrapped_callback(request, *callback_args, **callback_kwargs)
  File "C:\Users\HONG0\.conda\envs\py36\lib\site-packages\django\views\generic\base.py", line 70, in view
    return self.dispatch(request, *args, **kwargs)
  File "C:\Users\HONG0\.conda\envs\py36\lib\site-packages\django\views\generic\base.py", line 98, in dispatch
    return handler(request, *args, **kwargs)
  File "F:\NUS-ISS Intelligent Systems\ProjectModule\django_app\example_app\views.py", line 61, in post
    }, status=200)
  File "C:\Users\HONG0\.conda\envs\py36\lib\site-packages\django\http\response.py", line 567, in __init__
    data = json.dumps(data, cls=encoder, **json_dumps_params)
  File "C:\Users\HONG0\.conda\envs\py36\lib\json\__init__.py", line 238, in dumps
    **kw).encode(obj)
  File "C:\Users\HONG0\.conda\envs\py36\lib\json\encoder.py", line 199, in encode
    chunks = self.iterencode(o, _one_shot=True)
  File "C:\Users\HONG0\.conda\envs\py36\lib\json\encoder.py", line 257, in iterencode
    return _iterencode(o, 0)
  File "C:\Users\HONG0\.conda\envs\py36\lib\site-packages\django\core\serializers\json.py", line 105, in default
    return super().default(o)
  File "C:\Users\HONG0\.conda\envs\py36\lib\json\encoder.py", line 180, in default
    o.__class__.__name__)
TypeError: Object of type 'Statement' is not JSON serializable
"POST /api/chatterbot/ HTTP/1.1" 500 103180
F:\NUS-ISS Intelligent Systems\ProjectModule\django_app\example_app\views.py changed, reloading.
Watching for file changes with StatReloader
"GET / HTTP/1.1" 200 3766
Internal Server Error: /api/chatterbot/
Traceback (most recent call last):
  File "C:\Users\HONG0\.conda\envs\py36\lib\site-packages\django\core\handlers\exception.py", line 47, in inner
    response = get_response(request)
  File "C:\Users\HONG0\.conda\envs\py36\lib\site-packages\django\core\handlers\base.py", line 181, in _get_response
    response = wrapped_callback(request, *callback_args, **callback_kwargs)
  File "C:\Users\HONG0\.conda\envs\py36\lib\site-packages\django\views\generic\base.py", line 70, in view
    return self.dispatch(request, *args, **kwargs)
  File "C:\Users\HONG0\.conda\envs\py36\lib\site-packages\django\views\generic\base.py", line 98, in dispatch
    return handler(request, *args, **kwargs)
  File "F:\NUS-ISS Intelligent Systems\ProjectModule\django_app\example_app\views.py", line 61, in post
    }, status=200)
  File "C:\Users\HONG0\.conda\envs\py36\lib\site-packages\django\http\response.py", line 567, in __init__
    data = json.dumps(data, cls=encoder, **json_dumps_params)
  File "C:\Users\HONG0\.conda\envs\py36\lib\json\__init__.py", line 238, in dumps
    **kw).encode(obj)
  File "C:\Users\HONG0\.conda\envs\py36\lib\json\encoder.py", line 199, in encode
    chunks = self.iterencode(o, _one_shot=True)
  File "C:\Users\HONG0\.conda\envs\py36\lib\json\encoder.py", line 257, in iterencode
    return _iterencode(o, 0)
  File "C:\Users\HONG0\.conda\envs\py36\lib\site-packages\django\core\serializers\json.py", line 105, in default
    return super().default(o)
  File "C:\Users\HONG0\.conda\envs\py36\lib\json\encoder.py", line 180, in default
    o.__class__.__name__)
TypeError: Object of type 'Statement' is not JSON serializable
"POST /api/chatterbot/ HTTP/1.1" 500 102959
F:\NUS-ISS Intelligent Systems\ProjectModule\django_app\example_app\views.py changed, reloading.
Watching for file changes with StatReloader
Internal Server Error: /api/chatterbot/
Traceback (most recent call last):
  File "C:\Users\HONG0\.conda\envs\py36\lib\site-packages\django\core\handlers\exception.py", line 47, in inner
    response = get_response(request)
  File "C:\Users\HONG0\.conda\envs\py36\lib\site-packages\django\core\handlers\base.py", line 181, in _get_response
    response = wrapped_callback(request, *callback_args, **callback_kwargs)
  File "C:\Users\HONG0\.conda\envs\py36\lib\site-packages\django\views\generic\base.py", line 70, in view
    return self.dispatch(request, *args, **kwargs)
  File "C:\Users\HONG0\.conda\envs\py36\lib\site-packages\django\views\generic\base.py", line 98, in dispatch
    return handler(request, *args, **kwargs)
  File "F:\NUS-ISS Intelligent Systems\ProjectModule\django_app\example_app\views.py", line 61, in post
    }, status=200)
  File "C:\Users\HONG0\.conda\envs\py36\lib\site-packages\django\http\response.py", line 567, in __init__
    data = json.dumps(data, cls=encoder, **json_dumps_params)
  File "C:\Users\HONG0\.conda\envs\py36\lib\json\__init__.py", line 238, in dumps
    **kw).encode(obj)
  File "C:\Users\HONG0\.conda\envs\py36\lib\json\encoder.py", line 199, in encode
    chunks = self.iterencode(o, _one_shot=True)
  File "C:\Users\HONG0\.conda\envs\py36\lib\json\encoder.py", line 257, in iterencode
    return _iterencode(o, 0)
  File "C:\Users\HONG0\.conda\envs\py36\lib\site-packages\django\core\serializers\json.py", line 105, in default
    return super().default(o)
  File "C:\Users\HONG0\.conda\envs\py36\lib\json\encoder.py", line 180, in default
    o.__class__.__name__)
TypeError: Object of type 'Statement' is not JSON serializable
"POST /api/chatterbot/ HTTP/1.1" 500 102959
F:\NUS-ISS Intelligent Systems\ProjectModule\django_app\example_app\views.py changed, reloading.
Watching for file changes with StatReloader
"GET / HTTP/1.1" 200 3766
Internal Server Error: /api/chatterbot/
Traceback (most recent call last):
  File "C:\Users\HONG0\.conda\envs\py36\lib\site-packages\django\core\handlers\exception.py", line 47, in inner
    response = get_response(request)
  File "C:\Users\HONG0\.conda\envs\py36\lib\site-packages\django\core\handlers\base.py", line 181, in _get_response
    response = wrapped_callback(request, *callback_args, **callback_kwargs)
  File "C:\Users\HONG0\.conda\envs\py36\lib\site-packages\django\views\generic\base.py", line 70, in view
    return self.dispatch(request, *args, **kwargs)
  File "C:\Users\HONG0\.conda\envs\py36\lib\site-packages\django\views\generic\base.py", line 98, in dispatch
    return handler(request, *args, **kwargs)
  File "F:\NUS-ISS Intelligent Systems\ProjectModule\django_app\example_app\views.py", line 57, in post
    return JsonResponse(response_data, status=200)
  File "C:\Users\HONG0\.conda\envs\py36\lib\site-packages\django\http\response.py", line 561, in __init__
    'In order to allow non-dict objects to be serialized set the '
TypeError: In order to allow non-dict objects to be serialized set the safe parameter to False.
"POST /api/chatterbot/ HTTP/1.1" 500 82411
F:\NUS-ISS Intelligent Systems\ProjectModule\django_app\example_app\views.py changed, reloading.
Watching for file changes with StatReloader
"GET / HTTP/1.1" 200 3766
"POST /api/chatterbot/ HTTP/1.1" 200 299
"GET / HTTP/1.1" 200 3766
"GET / HTTP/1.1" 200 3766
"POST /api/chatterbot/ HTTP/1.1" 200 299
F:\NUS-ISS Intelligent Systems\ProjectModule\django_app\example_app\views.py changed, reloading.
Watching for file changes with StatReloader
F:\NUS-ISS Intelligent Systems\ProjectModule\django_app\example_app\settings.py changed, reloading.
Watching for file changes with StatReloader
Watching for file changes with StatReloader
"GET / HTTP/1.1" 200 3766
"POST /api/chatterbot/ HTTP/1.1" 200 299
F:\NUS-ISS Intelligent Systems\ProjectModule\django_app\example_app\settings.py changed, reloading.
Watching for file changes with StatReloader
Watching for file changes with StatReloader
"GET / HTTP/1.1" 200 3766
"POST /api/chatterbot/ HTTP/1.1" 200 299
F:\NUS-ISS Intelligent Systems\ProjectModule\django_app\example_app\settings.py changed, reloading.
Watching for file changes with StatReloader
"GET / HTTP/1.1" 200 3766
"POST /api/chatterbot/ HTTP/1.1" 200 299
F:\NUS-ISS Intelligent Systems\ProjectModule\django_app\example_app\views.py changed, reloading.
Watching for file changes with StatReloader
"GET / HTTP/1.1" 200 3766
"POST /api/chatterbot/ HTTP/1.1" 200 253
Watching for file changes with StatReloader
"GET / HTTP/1.1" 200 3766
"POST /api/chatterbot/ HTTP/1.1" 200 253
Watching for file changes with StatReloader
"GET / HTTP/1.1" 200 3766
"POST /api/chatterbot/ HTTP/1.1" 200 253
F:\NUS-ISS Intelligent Systems\ProjectModule\django_app\example_app\views.py changed, reloading.
Watching for file changes with StatReloader
"GET / HTTP/1.1" 200 3766
"POST /api/chatterbot/ HTTP/1.1" 200 253
"GET / HTTP/1.1" 200 3766
F:\NUS-ISS Intelligent Systems\ProjectModule\django_app\example_app\views.py changed, reloading.
Watching for file changes with StatReloader
F:\NUS-ISS Intelligent Systems\ProjectModule\django_app\example_app\views.py changed, reloading.
Watching for file changes with StatReloader
F:\NUS-ISS Intelligent Systems\ProjectModule\django_app\example_app\views.py changed, reloading.
Watching for file changes with StatReloader
Watching for file changes with StatReloader
Watching for file changes with StatReloader
F:\NUS-ISS Intelligent Systems\ProjectModule\django_app\example_app\views.py changed, reloading.
Watching for file changes with StatReloader
Watching for file changes with StatReloader
Watching for file changes with StatReloader
Watching for file changes with StatReloader
F:\NUS-ISS Intelligent Systems\ProjectModule\django_app\example_app\chatter.py changed, reloading.
Watching for file changes with StatReloader
Internal Server Error: /api/chatterbot/
Traceback (most recent call last):
  File "C:\Users\HONG0\.conda\envs\py36\lib\site-packages\django\core\handlers\exception.py", line 47, in inner
    response = get_response(request)
  File "C:\Users\HONG0\.conda\envs\py36\lib\site-packages\django\core\handlers\base.py", line 181, in _get_response
    response = wrapped_callback(request, *callback_args, **callback_kwargs)
  File "C:\Users\HONG0\.conda\envs\py36\lib\site-packages\django\views\generic\base.py", line 70, in view
    return self.dispatch(request, *args, **kwargs)
  File "C:\Users\HONG0\.conda\envs\py36\lib\site-packages\django\views\generic\base.py", line 98, in dispatch
    return handler(request, *args, **kwargs)
  File "F:\NUS-ISS Intelligent Systems\ProjectModule\django_app\example_app\views.py", line 61, in post
    response = chatter.get_answer(covid_faq_chatbot, covid_nlp_chatbot, question, threshold)
NameError: name 'covid_faq_chatbot' is not defined
"POST /api/chatterbot/ HTTP/1.1" 500 76867
F:\NUS-ISS Intelligent Systems\ProjectModule\django_app\example_app\views.py changed, reloading.
Watching for file changes with StatReloader
F:\NUS-ISS Intelligent Systems\ProjectModule\django_app\example_app\views.py changed, reloading.
Watching for file changes with StatReloader
"GET / HTTP/1.1" 200 3766
"POST /api/chatterbot/ HTTP/1.1" 200 358
"GET / HTTP/1.1" 200 3766
"POST /api/chatterbot/ HTTP/1.1" 200 358
"POST /api/chatterbot/ HTTP/1.1" 200 358
Internal Server Error: /api/chatterbot/
Traceback (most recent call last):
  File "C:\Users\HONG0\.conda\envs\py36\lib\site-packages\django\core\handlers\exception.py", line 47, in inner
    response = get_response(request)
  File "C:\Users\HONG0\.conda\envs\py36\lib\site-packages\django\core\handlers\base.py", line 181, in _get_response
    response = wrapped_callback(request, *callback_args, **callback_kwargs)
  File "C:\Users\HONG0\.conda\envs\py36\lib\site-packages\django\views\generic\base.py", line 70, in view
    return self.dispatch(request, *args, **kwargs)
  File "C:\Users\HONG0\.conda\envs\py36\lib\site-packages\django\views\generic\base.py", line 98, in dispatch
    return handler(request, *args, **kwargs)
  File "F:\NUS-ISS Intelligent Systems\ProjectModule\django_app\example_app\views.py", line 62, in post
    response_data = response.serialize()
AttributeError: 'str' object has no attribute 'serialize'
"POST /api/chatterbot/ HTTP/1.1" 500 77436
F:\NUS-ISS Intelligent Systems\ProjectModule\django_app\example_app\chatter.py changed, reloading.
Watching for file changes with StatReloader
"GET / HTTP/1.1" 200 3766
Internal Server Error: /api/chatterbot/
Traceback (most recent call last):
  File "C:\Users\HONG0\.conda\envs\py36\lib\site-packages\django\core\handlers\exception.py", line 47, in inner
    response = get_response(request)
  File "C:\Users\HONG0\.conda\envs\py36\lib\site-packages\django\core\handlers\base.py", line 181, in _get_response
    response = wrapped_callback(request, *callback_args, **callback_kwargs)
  File "C:\Users\HONG0\.conda\envs\py36\lib\site-packages\django\views\generic\base.py", line 70, in view
    return self.dispatch(request, *args, **kwargs)
  File "C:\Users\HONG0\.conda\envs\py36\lib\site-packages\django\views\generic\base.py", line 98, in dispatch
    return handler(request, *args, **kwargs)
  File "F:\NUS-ISS Intelligent Systems\ProjectModule\django_app\example_app\views.py", line 62, in post
    response_data = response.serialize()
AttributeError: 'str' object has no attribute 'serialize'
"POST /api/chatterbot/ HTTP/1.1" 500 77436
F:\NUS-ISS Intelligent Systems\ProjectModule\django_app\example_app\views.py changed, reloading.
Watching for file changes with StatReloader
"GET / HTTP/1.1" 200 3766
"POST /api/chatterbot/ HTTP/1.1" 200 290
"POST /api/chatterbot/ HTTP/1.1" 200 121
F:\NUS-ISS Intelligent Systems\ProjectModule\django_app\example_app\urls.py changed, reloading.
Watching for file changes with StatReloader
Not Found: /chatbot
"GET /chatbot HTTP/1.1" 404 2212
"GET /chatterbot HTTP/1.1" 301 0
Internal Server Error: /chatterbot/
Traceback (most recent call last):
  File "C:\Users\HONG0\.conda\envs\py36\lib\site-packages\django\core\handlers\exception.py", line 47, in inner
    response = get_response(request)
  File "C:\Users\HONG0\.conda\envs\py36\lib\site-packages\django\core\handlers\base.py", line 181, in _get_response
    response = wrapped_callback(request, *callback_args, **callback_kwargs)
  File "C:\Users\HONG0\.conda\envs\py36\lib\site-packages\django\views\generic\base.py", line 70, in view
    return self.dispatch(request, *args, **kwargs)
  File "C:\Users\HONG0\.conda\envs\py36\lib\site-packages\django\views\generic\base.py", line 98, in dispatch
    return handler(request, *args, **kwargs)
  File "F:\NUS-ISS Intelligent Systems\ProjectModule\django_app\example_app\views.py", line 75, in get
    'name': self.chatterbot.name
AttributeError: 'ChatterBotApiView' object has no attribute 'chatterbot'
"GET /chatterbot/ HTTP/1.1" 500 75592
F:\NUS-ISS Intelligent Systems\ProjectModule\django_app\example_app\urls.py changed, reloading.
Watching for file changes with StatReloader
Internal Server Error: /api/chatterbot/
Traceback (most recent call last):
  File "C:\Users\HONG0\.conda\envs\py36\lib\site-packages\django\core\handlers\exception.py", line 47, in inner
    response = get_response(request)
  File "C:\Users\HONG0\.conda\envs\py36\lib\site-packages\django\core\handlers\base.py", line 181, in _get_response
    response = wrapped_callback(request, *callback_args, **callback_kwargs)
  File "C:\Users\HONG0\.conda\envs\py36\lib\site-packages\django\views\generic\base.py", line 70, in view
    return self.dispatch(request, *args, **kwargs)
  File "C:\Users\HONG0\.conda\envs\py36\lib\site-packages\django\views\generic\base.py", line 98, in dispatch
    return handler(request, *args, **kwargs)
  File "F:\NUS-ISS Intelligent Systems\ProjectModule\django_app\example_app\views.py", line 75, in get
    'name': self.chatterbot.name
AttributeError: 'ChatterBotApiView' object has no attribute 'chatterbot'
"GET /api/chatterbot/ HTTP/1.1" 500 75777
Internal Server Error: /api/chatterbot/
Traceback (most recent call last):
  File "C:\Users\HONG0\.conda\envs\py36\lib\site-packages\django\core\handlers\exception.py", line 47, in inner
    response = get_response(request)
  File "C:\Users\HONG0\.conda\envs\py36\lib\site-packages\django\core\handlers\base.py", line 181, in _get_response
    response = wrapped_callback(request, *callback_args, **callback_kwargs)
  File "C:\Users\HONG0\.conda\envs\py36\lib\site-packages\django\views\generic\base.py", line 70, in view
    return self.dispatch(request, *args, **kwargs)
  File "C:\Users\HONG0\.conda\envs\py36\lib\site-packages\django\views\generic\base.py", line 98, in dispatch
    return handler(request, *args, **kwargs)
  File "F:\NUS-ISS Intelligent Systems\ProjectModule\django_app\example_app\views.py", line 75, in get
    'name': self.chatterbot.name
AttributeError: 'ChatterBotApiView' object has no attribute 'chatterbot'
"GET /api/chatterbot/ HTTP/1.1" 500 75777
"GET / HTTP/1.1" 200 3766
F:\NUS-ISS Intelligent Systems\ProjectModule\django_app\example_app\urls.py changed, reloading.
Watching for file changes with StatReloader
Internal Server Error: /api/chatterbot/
Traceback (most recent call last):
  File "C:\Users\HONG0\.conda\envs\py36\lib\site-packages\django\core\handlers\exception.py", line 47, in inner
    response = get_response(request)
  File "C:\Users\HONG0\.conda\envs\py36\lib\site-packages\django\core\handlers\base.py", line 181, in _get_response
    response = wrapped_callback(request, *callback_args, **callback_kwargs)
  File "C:\Users\HONG0\.conda\envs\py36\lib\site-packages\django\views\generic\base.py", line 70, in view
    return self.dispatch(request, *args, **kwargs)
  File "C:\Users\HONG0\.conda\envs\py36\lib\site-packages\django\views\generic\base.py", line 98, in dispatch
    return handler(request, *args, **kwargs)
  File "F:\NUS-ISS Intelligent Systems\ProjectModule\django_app\example_app\views.py", line 75, in get
    'name': self.chatterbot.name
AttributeError: 'ChatterBotApiView' object has no attribute 'chatterbot'
"GET /api/chatterbot/ HTTP/1.1" 500 75640
"GET /admin HTTP/1.1" 301 0
"GET /admin/ HTTP/1.1" 302 0
"GET /admin/login/?next=/admin/ HTTP/1.1" 200 2194
"GET /static/admin/css/nav_sidebar.css HTTP/1.1" 200 2138
"GET /static/admin/css/login.css HTTP/1.1" 200 1185
"GET /static/admin/css/base.css HTTP/1.1" 200 16307
"GET /static/admin/css/responsive.css HTTP/1.1" 200 18344
"GET /static/admin/js/nav_sidebar.js HTTP/1.1" 200 1360
"GET /admin/ HTTP/1.1" 302 0
"GET /admin/login/?next=/admin/ HTTP/1.1" 200 2194
"GET /static/admin/css/fonts.css HTTP/1.1" 200 423
"GET /static/admin/fonts/Roboto-Light-webfont.woff HTTP/1.1" 200 85692
"GET /static/admin/fonts/Roboto-Regular-webfont.woff HTTP/1.1" 200 85876
F:\NUS-ISS Intelligent Systems\ProjectModule\django_app\example_app\urls.py changed, reloading.
Watching for file changes with StatReloader
Not Found: /api/chatterbot/
"GET /api/chatterbot/ HTTP/1.1" 404 2222
Not Found: /chatterbot/
"GET /chatterbot/ HTTP/1.1" 404 2210
"GET /app HTTP/1.1" 301 0
Internal Server Error: /app/
Traceback (most recent call last):
  File "C:\Users\HONG0\.conda\envs\py36\lib\site-packages\django\core\handlers\exception.py", line 47, in inner
    response = get_response(request)
  File "C:\Users\HONG0\.conda\envs\py36\lib\site-packages\django\core\handlers\base.py", line 181, in _get_response
    response = wrapped_callback(request, *callback_args, **callback_kwargs)
  File "C:\Users\HONG0\.conda\envs\py36\lib\site-packages\django\views\generic\base.py", line 70, in view
    return self.dispatch(request, *args, **kwargs)
  File "C:\Users\HONG0\.conda\envs\py36\lib\site-packages\django\views\generic\base.py", line 98, in dispatch
    return handler(request, *args, **kwargs)
  File "F:\NUS-ISS Intelligent Systems\ProjectModule\django_app\example_app\views.py", line 75, in get
    'name': self.chatterbot.name
AttributeError: 'ChatterBotApiView' object has no attribute 'chatterbot'
"GET /app/ HTTP/1.1" 500 75508
F:\NUS-ISS Intelligent Systems\ProjectModule\django_app\example_app\urls.py changed, reloading.
Watching for file changes with StatReloader
Not Found: /app/
"GET /app/ HTTP/1.1" 404 2197
"GET /chatbot HTTP/1.1" 301 0
Internal Server Error: /chatbot/
Traceback (most recent call last):
  File "C:\Users\HONG0\.conda\envs\py36\lib\site-packages\django\core\handlers\exception.py", line 47, in inner
    response = get_response(request)
  File "C:\Users\HONG0\.conda\envs\py36\lib\site-packages\django\core\handlers\base.py", line 204, in _get_response
    response = response.render()
  File "C:\Users\HONG0\.conda\envs\py36\lib\site-packages\django\template\response.py", line 105, in render
    self.content = self.rendered_content
  File "C:\Users\HONG0\.conda\envs\py36\lib\site-packages\django\template\response.py", line 83, in rendered_content
    return template.render(context, self._request)
  File "C:\Users\HONG0\.conda\envs\py36\lib\site-packages\django\template\backends\django.py", line 61, in render
    return self.template.render(context)
  File "C:\Users\HONG0\.conda\envs\py36\lib\site-packages\django\template\base.py", line 170, in render
    return self._render(context)
  File "C:\Users\HONG0\.conda\envs\py36\lib\site-packages\django\template\base.py", line 162, in _render
    return self.nodelist.render(context)
  File "C:\Users\HONG0\.conda\envs\py36\lib\site-packages\django\template\base.py", line 938, in render
    bit = node.render_annotated(context)
  File "C:\Users\HONG0\.conda\envs\py36\lib\site-packages\django\template\base.py", line 905, in render_annotated
    return self.render(context)
  File "C:\Users\HONG0\.conda\envs\py36\lib\site-packages\django\template\loader_tags.py", line 192, in render
    return template.render(context)
  File "C:\Users\HONG0\.conda\envs\py36\lib\site-packages\django\template\base.py", line 172, in render
    return self._render(context)
  File "C:\Users\HONG0\.conda\envs\py36\lib\site-packages\django\template\base.py", line 162, in _render
    return self.nodelist.render(context)
  File "C:\Users\HONG0\.conda\envs\py36\lib\site-packages\django\template\base.py", line 938, in render
    bit = node.render_annotated(context)
  File "C:\Users\HONG0\.conda\envs\py36\lib\site-packages\django\template\base.py", line 905, in render_annotated
    return self.render(context)
  File "C:\Users\HONG0\.conda\envs\py36\lib\site-packages\django\template\defaulttags.py", line 446, in render
    url = reverse(view_name, args=args, kwargs=kwargs, current_app=current_app)
  File "C:\Users\HONG0\.conda\envs\py36\lib\site-packages\django\urls\base.py", line 87, in reverse
    return iri_to_uri(resolver._reverse_with_prefix(view, prefix, *args, **kwargs))
  File "C:\Users\HONG0\.conda\envs\py36\lib\site-packages\django\urls\resolvers.py", line 685, in _reverse_with_prefix
    raise NoReverseMatch(msg)
django.urls.exceptions.NoReverseMatch: Reverse for 'chatterbot' not found. 'chatterbot' is not a valid view function or pattern name.
"GET /chatbot/ HTTP/1.1" 500 136353
F:\NUS-ISS Intelligent Systems\ProjectModule\django_app\example_app\urls.py changed, reloading.
Watching for file changes with StatReloader
"GET /chatbot/ HTTP/1.1" 200 3752
Watching for file changes with StatReloader
"GET / HTTP/1.1" 200 3752
"GET /static/css/custom.css HTTP/1.1" 200 183
"GET /static/css/bootstrap.css HTTP/1.1" 200 105310
"GET /static/js/js.cookie.js HTTP/1.1" 200 1615
"GET /static/img/chatterbot.png HTTP/1.1" 200 6895
"GET /static/js/jquery.js HTTP/1.1" 200 261746
"GET /static/js/bootstrap.js HTTP/1.1" 200 44636
Not Found: /favicon.ico
"GET /favicon.ico HTTP/1.1" 404 2221
"GET /chatbot HTTP/1.1" 301 0
"GET /chatbot/ HTTP/1.1" 200 3752
